time 0ms: Simulator started for FCFS [Q empty]
time 319ms: Process A0 arrived; added to ready queue [Q A0]
time 321ms: Process A0 started using the CPU for 1448ms burst [Q empty]
time 506ms: Process A1 arrived; added to ready queue [Q A1]
time 821ms: Process A2 arrived; added to ready queue [Q A1 A2]
time 1769ms: Process A0 completed a CPU burst; 24 bursts to go [Q A1 A2]
time 1769ms: Process A0 switching out of CPU; blocking on I/O until time 2379ms [Q A1 A2]
time 1773ms: Process A1 started using the CPU for 971ms burst [Q A2]
time 2379ms: Process A0 completed I/O; added to ready queue [Q A2]
time 2744ms: Process A1 completed a CPU burst; 4 bursts to go [Q A2 A0]
time 2744ms: Process A1 switching out of CPU; blocking on I/O until time 3178ms [Q A2 A0]
time 2748ms: Process A2 started using the CPU for 408ms burst [Q A0]
time 3156ms: Process A2 completed a CPU burst; 14 bursts to go [Q A0]
time 3156ms: Process A2 switching out of CPU; blocking on I/O until time 8670ms [Q A0]
time 3160ms: Process A0 started using the CPU for 316ms burst [Q empty]
time 3178ms: Process A1 completed I/O; added to ready queue [Q empty]
time 3476ms: Process A0 completed a CPU burst; 23 bursts to go [Q A1]
time 3476ms: Process A0 switching out of CPU; blocking on I/O until time 4086ms [Q A1]
time 3480ms: Process A1 started using the CPU for 129ms burst [Q empty]
time 3609ms: Process A1 completed a CPU burst; 3 bursts to go [Q empty]
time 3609ms: Process A1 switching out of CPU; blocking on I/O until time 4043ms [Q empty]
time 4043ms: Process A1 completed I/O; added to ready queue [Q empty]
time 4047ms: Process A1 started using the CPU for 188ms burst [Q empty]
time 4086ms: Process A0 completed I/O; added to ready queue [Q empty]
time 4235ms: Process A1 completed a CPU burst; 2 bursts to go [Q A0]
time 4235ms: Process A1 switching out of CPU; blocking on I/O until time 4669ms [Q A0]
time 4239ms: Process A0 started using the CPU for 3556ms burst [Q empty]
time 4669ms: Process A1 completed I/O; added to ready queue [Q empty]
time 7795ms: Process A0 completed a CPU burst; 22 bursts to go [Q A1]
time 7795ms: Process A0 switching out of CPU; blocking on I/O until time 8405ms [Q A1]
time 7799ms: Process A1 started using the CPU for 302ms burst [Q empty]
time 8101ms: Process A1 completed a CPU burst; 1 bursts to go [Q empty]
time 8101ms: Process A1 switching out of CPU; blocking on I/O until time 8535ms [Q empty]
time 8405ms: Process A0 completed I/O; added to ready queue [Q empty]
time 8409ms: Process A0 started using the CPU for 2516ms burst [Q empty]
time 8535ms: Process A1 completed I/O; added to ready queue [Q empty]
time 8670ms: Process A2 completed I/O; added to ready queue [Q A1]
time 10925ms: Process A0 completed a CPU burst; 21 bursts to go [Q A1 A2]
time 10925ms: Process A0 switching out of CPU; blocking on I/O until time 11535ms [Q A1 A2]
time 10929ms: Process A1 started using the CPU for 73ms burst [Q A2]
time 11002ms: Process A1 completed a CPU burst; 0 bursts to go [Q A2]
time 11002ms: Process A1 switching out of CPU; blocking on I/O until time 11436ms [Q A2]
time 11006ms: Process A2 started using the CPU for 182ms burst [Q empty]
time 11188ms: Process A2 completed a CPU burst; 13 bursts to go [Q empty]
time 11188ms: Process A2 switching out of CPU; blocking on I/O until time 16702ms [Q empty]
time 11436ms: Process A1 completed I/O; added to ready queue [Q empty]
time 11535ms: Process A0 completed I/O; added to ready queue [Q A1]
time 16702ms: Process A2 completed I/O; added to ready queue [Q A1 A0]